<?xml version="1.0" ?>
<!-- =================================================================================== -->
<!-- |    This document was autogenerated by xacro from rover_description.urdf         | -->
<!-- |    EDITING THIS FILE BY HAND IS NOT RECOMMENDED                                 | -->
<!-- =================================================================================== -->
<robot name="rover">
  <!-- Robot Base -->
  <link name="base_link">
    <origin rpy="0.0 0.0 0.0" xyz="0.0 0.0 0.0"/>
    <visual>
      <origin rpy="0.0 0.0 0.0" xyz="-0.06 0.0 0.0"/>
      <geometry>
        <box size="0.68 0.31 0.18"/>
      </geometry>
      <material name="Cyan">
        <color rgba="0 1.0 1.0 1.0"/>
      </material>
    </visual>
    <visual>
      <origin rpy="0.0 0.0 0.0" xyz="0.37 0.0 0.0"/>
      <geometry>
        <box size="0.18 0.31 0.08"/>
      </geometry>
    </visual>
    <collision>
      <origin rpy="0.0 0.0 0.0" xyz="-0.06 0.0 0.0"/>
      <geometry>
        <box size="0.68 0.31 0.18"/>
      </geometry>
    </collision>
    <collision>
      <origin rpy="0.0 0.0 0.0" xyz="0.37 0.0 0.0"/>
      <geometry>
        <box size="0.18 0.31 0.08"/>
      </geometry>
    </collision>
    <inertial>
      <origin rpy="1.5707963267948966 0 1.5707963267948966" xyz="-0.06 0 0"/>
      <mass value="15"/>
      <inertia ixx="0.16062500000000002" ixy="0.0" ixz="0.0" iyy="0.6981250000000001" iyz="0.0" izz="0.6185"/>
    </inertial>
    <inertial>
      <origin rpy="1.5707963267948966 0 1.5707963267948966" xyz="0.37 0 0"/>
      <mass value="1"/>
      <inertia ixx="0.008541666666666666" ixy="0.0" ixz="0.0" iyy="0.010708333333333334" iyz="0.0" izz="0.0032333333333333333"/>
    </inertial>
  </link>
  <!-- Robot Footprint -->
  <link name="base_footprint"/>
  <joint name="base_joint" type="fixed">
    <parent link="base_footprint"/>
    <child link="base_link"/>
    <origin rpy="0 0 0" xyz="0.0 0.0 0.4"/>
  </joint>
  <link name="bogey_l_link">
    <visual>
      <origin rpy="0.0 0.0 0.0" xyz="0.0 0.0 0.0"/>
      <geometry>
        <box size="0.54 0.065 0.065"/>
      </geometry>
    </visual>
    <collision>
      <origin rpy="0.0 0.0 0.0" xyz="0.0 0.0 0.0"/>
      <geometry>
        <box size="0.54 0.065 0.065"/>
      </geometry>
    </collision>
    <inertial>
      <origin rpy="1.5707963267948966 0 1.5707963267948966" xyz="0 0 0"/>
      <mass value="1"/>
      <inertia ixx="0.02465208333333333" ixy="0.0" ixz="0.0" iyy="0.02465208333333333" iyz="0.0" izz="0.0007041666666666667"/>
    </inertial>
  </link>
  <joint name="bogey_l_joint" type="fixed">
    <!-- <limit effort="1000.0" lower="-0.5" upper="0.5" velocity="0.5"/> -->
    <parent link="base_link"/>
    <child link="bogey_l_link"/>
    <origin rpy="0.0 0.0 0.0" xyz="0.225 0.1875 -0.05"/>
    <axis xyz="0 1 0"/>
  </joint>
  <link name="bogey_r_link">
    <visual>
      <origin rpy="0.0 0.0 0.0" xyz="0.0 0.0 0.0"/>
      <geometry>
        <box size="0.54 0.065 0.065"/>
      </geometry>
    </visual>
    <collision>
      <origin rpy="0.0 0.0 0.0" xyz="0.0 0.0 0.0"/>
      <geometry>
        <box size="0.54 0.065 0.065"/>
      </geometry>
    </collision>
    <inertial>
      <origin rpy="1.5707963267948966 0 1.5707963267948966" xyz="0 0 0"/>
      <mass value="1"/>
      <inertia ixx="0.02465208333333333" ixy="0.0" ixz="0.0" iyy="0.02465208333333333" iyz="0.0" izz="0.0007041666666666667"/>
    </inertial>
  </link>
  <joint name="bogey_r_joint" type="fixed">
    <!-- <limit effort="1000.0" lower="-0.5" upper="0.5" velocity="0.5"/> -->
    <parent link="base_link"/>
    <child link="bogey_r_link"/>
    <origin rpy="0.0 0.0 0.0" xyz="0.225 -0.1875 -0.05"/>
    <axis xyz="0 1 0"/>
  </joint>
  <link name="bogey_b_link">
    <visual>
      <origin rpy="0.0 0.0 0.0" xyz="0.0 0.0 0.0"/>
      <geometry>
        <box size="0.065 0.44 0.065"/>
      </geometry>
    </visual>
    <collision>
      <origin rpy="0.0 0.0 0.0" xyz="0.0 0.0 0.0"/>
      <geometry>
        <box size="0.065 0.375 0.065"/>
      </geometry>
    </collision>
    <inertial>
      <origin rpy="1.5707963267948966 0 1.5707963267948966" xyz="0 0 0"/>
      <mass value="1"/>
      <inertia ixx="0.0007041666666666667" ixy="0.0" ixz="0.0" iyy="0.016485416666666666" iyz="0.0" izz="0.016485416666666666"/>
    </inertial>
  </link>
  <joint name="bogey_b_joint" type="fixed">
    <parent link="base_link"/>
    <child link="bogey_b_link"/>
    <origin rpy="0.0 0.0 0.0" xyz="-0.45 0.0 -0.05"/>
  </joint>
  <link name="wheel_l_f_link">
    <visual>
      <origin rpy="1.5707963267948966 0 0" xyz="0 0 0"/>
      <geometry>
        <cylinder length="0.125" radius="0.15"/>
      </geometry>
      <material name="Gray">
        <color rgba="0.5 0.5 0.5 1.0"/>
      </material>
    </visual>
    <collision>
      <origin rpy="1.5707963267948966 0 0" xyz="0 0 0"/>
      <geometry>
        <cylinder length="0.125" radius="0.15"/>
      </geometry>
    </collision>
    <inertial>
      <origin rpy="1.5707963267948966 0 0" xyz="0 0 0"/>
      <mass value="1"/>
      <inertia ixx="0.006927083333333332" ixy="0" ixz="0" iyy="0.006927083333333332" iyz="0" izz="0.01125"/>
    </inertial>
  </link>
  <joint name="wheel_l_f_joint" type="continuous">
    <parent link="bogey_l_link"/>
    <child link="wheel_l_f_link"/>
    <origin rpy="0 0 0" xyz="0.225 0.095 -0.2"/>
    <axis xyz="0 1 0"/>
  </joint>
  <link name="wheel_l_m_link">
    <visual>
      <origin rpy="1.5707963267948966 0 0" xyz="0 0 0"/>
      <geometry>
        <cylinder length="0.125" radius="0.15"/>
      </geometry>
      <material name="Gray">
        <color rgba="0.5 0.5 0.5 1.0"/>
      </material>
    </visual>
    <collision>
      <origin rpy="1.5707963267948966 0 0" xyz="0 0 0"/>
      <geometry>
        <cylinder length="0.125" radius="0.15"/>
      </geometry>
    </collision>
    <inertial>
      <origin rpy="1.5707963267948966 0 0" xyz="0 0 0"/>
      <mass value="1"/>
      <inertia ixx="0.006927083333333332" ixy="0" ixz="0" iyy="0.006927083333333332" iyz="0" izz="0.01125"/>
    </inertial>
  </link>
  <joint name="wheel_l_m_joint" type="continuous">
    <parent link="bogey_l_link"/>
    <child link="wheel_l_m_link"/>
    <origin rpy="0 0 0" xyz="-0.225 0.095 -0.2"/>
    <axis xyz="0 1 0"/>
  </joint>
  <link name="wheel_l_b_link">
    <visual>
      <origin rpy="1.5707963267948966 0 0" xyz="0 0 0"/>
      <geometry>
        <cylinder length="0.125" radius="0.15"/>
      </geometry>
      <material name="Gray">
        <color rgba="0.5 0.5 0.5 1.0"/>
      </material>
    </visual>
    <collision>
      <origin rpy="1.5707963267948966 0 0" xyz="0 0 0"/>
      <geometry>
        <cylinder length="0.125" radius="0.15"/>
      </geometry>
    </collision>
    <inertial>
      <origin rpy="1.5707963267948966 0 0" xyz="0 0 0"/>
      <mass value="1"/>
      <inertia ixx="0.006927083333333332" ixy="0" ixz="0" iyy="0.006927083333333332" iyz="0" izz="0.01125"/>
    </inertial>
  </link>
  <joint name="wheel_l_b_joint" type="continuous">
    <parent link="bogey_b_link"/>
    <child link="wheel_l_b_link"/>
    <origin rpy="0 0 0" xyz="0 0.2825 -0.2"/>
    <axis xyz="0 1 0"/>
  </joint>
  <link name="wheel_r_f_link">
    <visual>
      <origin rpy="1.5707963267948966 0 0" xyz="0 0 0"/>
      <geometry>
        <cylinder length="0.125" radius="0.15"/>
      </geometry>
      <material name="Gray">
        <color rgba="0.5 0.5 0.5 1.0"/>
      </material>
    </visual>
    <collision>
      <origin rpy="1.5707963267948966 0 0" xyz="0 0 0"/>
      <geometry>
        <cylinder length="0.125" radius="0.15"/>
      </geometry>
    </collision>
    <inertial>
      <origin rpy="1.5707963267948966 0 0" xyz="0 0 0"/>
      <mass value="1"/>
      <inertia ixx="0.006927083333333332" ixy="0" ixz="0" iyy="0.006927083333333332" iyz="0" izz="0.01125"/>
    </inertial>
  </link>
  <joint name="wheel_r_f_joint" type="continuous">
    <parent link="bogey_r_link"/>
    <child link="wheel_r_f_link"/>
    <origin rpy="0 0 0" xyz="0.225 -0.095 -0.2"/>
    <axis xyz="0 1 0"/>
  </joint>
  <link name="wheel_r_m_link">
    <visual>
      <origin rpy="1.5707963267948966 0 0" xyz="0 0 0"/>
      <geometry>
        <cylinder length="0.125" radius="0.15"/>
      </geometry>
      <material name="Gray">
        <color rgba="0.5 0.5 0.5 1.0"/>
      </material>
    </visual>
    <collision>
      <origin rpy="1.5707963267948966 0 0" xyz="0 0 0"/>
      <geometry>
        <cylinder length="0.125" radius="0.15"/>
      </geometry>
    </collision>
    <inertial>
      <origin rpy="1.5707963267948966 0 0" xyz="0 0 0"/>
      <mass value="1"/>
      <inertia ixx="0.006927083333333332" ixy="0" ixz="0" iyy="0.006927083333333332" iyz="0" izz="0.01125"/>
    </inertial>
  </link>
  <joint name="wheel_r_m_joint" type="continuous">
    <parent link="bogey_r_link"/>
    <child link="wheel_r_m_link"/>
    <origin rpy="0 0 0" xyz="-0.225 -0.095 -0.2"/>
    <axis xyz="0 1 0"/>
  </joint>
  <link name="wheel_r_b_link">
    <visual>
      <origin rpy="1.5707963267948966 0 0" xyz="0 0 0"/>
      <geometry>
        <cylinder length="0.125" radius="0.15"/>
      </geometry>
      <material name="Gray">
        <color rgba="0.5 0.5 0.5 1.0"/>
      </material>
    </visual>
    <collision>
      <origin rpy="1.5707963267948966 0 0" xyz="0 0 0"/>
      <geometry>
        <cylinder length="0.125" radius="0.15"/>
      </geometry>
    </collision>
    <inertial>
      <origin rpy="1.5707963267948966 0 0" xyz="0 0 0"/>
      <mass value="1"/>
      <inertia ixx="0.006927083333333332" ixy="0" ixz="0" iyy="0.006927083333333332" iyz="0" izz="0.01125"/>
    </inertial>
  </link>
  <joint name="wheel_r_b_joint" type="continuous">
    <parent link="bogey_b_link"/>
    <child link="wheel_r_b_link"/>
    <origin rpy="0 0 0" xyz="0 -0.2825 -0.2"/>
    <axis xyz="0 1 0"/>
  </joint>
  <link name="os_sensor"/>
  <joint name="sensor_joint" type="fixed">
    <parent link="base_link"/>
    <child link="os_sensor"/>
    <origin xyz="0.37 0 0.12"/>
  </joint>
  <link name="os_imu"/>
  <joint name="imu_joint" type="fixed">
    <parent link="base_link"/>
    <child link="os_imu"/>
    <origin xyz="0.37 0 0.12"/>
  </joint>
  <link name="os_lidar">
    <inertial>
      <origin rpy="0 0 0" xyz="0 0 0"/>
      <mass value="0.125"/>
      <inertia ixx="0.001" ixy="0" ixz="0" iyy="0.001" iyz="0" izz="0.001"/>
    </inertial>
    <collision>
      <origin rpy="0 0 0" xyz="0 0 0"/>
      <geometry>
        <cylinder length="0.055" radius="0.0508"/>
      </geometry>
    </collision>
    <visual>
      <origin rpy="0 0 0" xyz="0 0 0"/>
      <geometry>
        <cylinder length="0.055" radius="0.0508"/>
      </geometry>
    </visual>
  </link>
  <joint name="lidar_joint" type="fixed">
    <parent link="base_link"/>
    <child link="os_lidar"/>
    <origin rpy="0 0 0" xyz="0.37 0 0.2"/>
  </joint>
  <link name="gps_link">
    <visual>
      <geometry>
        <box size="0.1 0.1 0.1"/>
      </geometry>
    </visual>
    <collision>
      <geometry>
        <box size="0.1 0.1 0.1"/>
      </geometry>
    </collision>
    <inertial>
      <origin rpy="1.5707963267948966 0 1.5707963267948966" xyz="0 0 0"/>
      <mass value="0.1"/>
      <inertia ixx="0.0001666666666666667" ixy="0.0" ixz="0.0" iyy="0.0001666666666666667" iyz="0.0" izz="0.0001666666666666667"/>
    </inertial>
  </link>
  <joint name="gps_joint" type="fixed">
    <parent link="base_link"/>
    <child link="gps_link"/>
    <origin rpy="0 0 0" xyz="0 0 0"/>
  </joint>
</robot>
