<?xml version="1.0" encoding="utf-8"?>
<!-- This URDF was automatically created by SolidWorks to URDF Exporter! Originally created by Stephen Brawner (brawner@gmail.com) 
     Commit Version: 1.5.1-0-g916b5db  Build Version: 1.5.7152.31018
     For more information, please see http://wiki.ros.org/sw_urdf_exporter -->
<robot
  name="colarm">
  <link
    name="base_link">
    <inertial>
      <origin
        xyz="1.342E-17 0.00175 0"
        rpy="0 0 0" />
      <mass
        value="0.37094" />
      <inertia
        ixx="0.0025643"
        ixy="5.2134E-22"
        ixz="-5.7244E-19"
        iyy="0.0067502"
        iyz="0"
        izz="0.0041866" />
    </inertial>
    <visual>
      <origin
        xyz="0 0 0"
        rpy="0 0 0" />
      <geometry>
        <mesh
          filename="package://colarm/meshes/base_link.STL" />
      </geometry>
      <material
        name="">
        <color
          rgba="0.79216 0.81961 0.93333 1" />
      </material>
    </visual>
    <collision>
      <origin
        xyz="0 0 0"
        rpy="0 0 0" />
      <geometry>
        <mesh
          filename="package://colarm/meshes/base_link.STL" />
      </geometry>
    </collision>
  </link>
  <link
    name="upbase_link">
    <inertial>
      <origin
        xyz="-1.3629E-16 0.005 -1.459E-14"
        rpy="0 0 0" />
      <mass
        value="0.20106" />
      <inertia
        ixx="0.00032337"
        ixy="-8.721E-18"
        ixz="0"
        iyy="0.0006434"
        iyz="-9.3345E-16"
        izz="0.00032337" />
    </inertial>
    <visual>
      <origin
        xyz="0 0 0"
        rpy="0 0 0" />
      <geometry>
        <mesh
          filename="package://colarm/meshes/upbase_link.STL" />
      </geometry>
      <material
        name="">
        <color
          rgba="0.79216 0.81961 0.93333 1" />
      </material>
    </visual>
    <collision>
      <origin
        xyz="0 0 0"
        rpy="0 0 0" />
      <geometry>
        <mesh
          filename="package://colarm/meshes/upbase_link.STL" />
      </geometry>
    </collision>
  </link>
  <joint
    name="upbase_joint"
    type="revolute">
    <origin
      xyz="0 0 0"
      rpy="1.5708 0 3.1322" />
    <parent
      link="base_link" />
    <child
      link="upbase_link" />
    <axis
      xyz="0 1 0" />
    <limit
      lower="-1.57"
      upper="1.57"
      effort="25"
      velocity="0.5" />
  </joint>
  <link
    name="prox_link">
    <inertial>
      <origin
        xyz="0.0022249 0.3694 0.0027483"
        rpy="0 0 0" />
      <mass
        value="8.5094" />
      <inertia
        ixx="0.078716"
        ixy="-5.827E-18"
        ixz="2.04E-06"
        iyy="0.018015"
        iyz="1.5993E-15"
        izz="0.080556" />
    </inertial>
    <visual>
      <origin
        xyz="0 0 0"
        rpy="0 0 0" />
      <geometry>
        <mesh
          filename="package://colarm/meshes/prox_link.STL" />
      </geometry>
      <material
        name="">
        <color
          rgba="0.79216 0.81961 0.93333 1" />
      </material>
    </visual>
    <collision>
      <origin
        xyz="0 0 0"
        rpy="0 0 0" />
      <geometry>
        <mesh
          filename="package://colarm/meshes/prox_link.STL" />
      </geometry>
    </collision>
  </link>
  <joint
    name="prox_joint"
    type="revolute">
    <origin
      xyz="-0.0031353 0.0935 0.0050186"
      rpy="3.1416 -0.0093664 3.1416" />
    <parent
      link="upbase_link" />
    <child
      link="prox_link" />
    <axis
      xyz="-0.54145 -0.84072 -0.0050716" />
    <limit
      lower="-1.57"
      upper="1.57"
      effort="25"
      velocity="0.5" />
  </joint>
  <link
    name="distal_link">
    <inertial>
      <origin
        xyz="0.00013587 0.23939 -0.00044913"
        rpy="0 0 0" />
      <mass
        value="3.0627" />
      <inertia
        ixx="0.035901"
        ixy="-3.3881E-20"
        ixz="-6.8097E-20"
        iyy="0.0033506"
        iyz="4.5175E-20"
        izz="0.036119" />
    </inertial>
    <visual>
      <origin
        xyz="0 0 0"
        rpy="0 0 0" />
      <geometry>
        <mesh
          filename="package://colarm/meshes/distal_link.STL" />
      </geometry>
      <material
        name="">
        <color
          rgba="0.79216 0.81961 0.93333 1" />
      </material>
    </visual>
    <collision>
      <origin
        xyz="0 0 0"
        rpy="0 0 0" />
      <geometry>
        <mesh
          filename="package://colarm/meshes/distal_link.STL" />
      </geometry>
    </collision>
  </link>
  <joint
    name="distal_joint"
    type="revolute">
    <origin
      xyz="0.0050063 0.43 0.006154"
      rpy="0 0 0" />
    <parent
      link="prox_link" />
    <child
      link="distal_link" />
    <axis
      xyz="0 0 0" />
    <limit
      lower="-1.57"
      upper="1.57"
      effort="25"
      velocity="0.5" />
  </joint>
  <link
    name="basewrist_link">
    <inertial>
      <origin
        xyz="3.1985E-06 0.041687 -2.6948E-05"
        rpy="0 0 0" />
      <mass
        value="0.2986" />
      <inertia
        ixx="0.0002408"
        ixy="1.3878E-21"
        ixz="-8.6736E-22"
        iyy="0.00017399"
        iyz="6.2572E-37"
        izz="0.0002408" />
    </inertial>
    <visual>
      <origin
        xyz="0 0 0"
        rpy="0 0 0" />
      <geometry>
        <mesh
          filename="package://colarm/meshes/basewrist_link.STL" />
      </geometry>
      <material
        name="">
        <color
          rgba="0.79216 0.81961 0.93333 1" />
      </material>
    </visual>
    <collision>
      <origin
        xyz="0 0 0"
        rpy="0 0 0" />
      <geometry>
        <mesh
          filename="package://colarm/meshes/basewrist_link.STL" />
      </geometry>
    </collision>
  </link>
  <joint
    name="basewrist_joint"
    type="revolute">
    <origin
      xyz="-0.00021009 0.48 -0.00075716"
      rpy="0 0 0" />
    <parent
      link="distal_link" />
    <child
      link="basewrist_link" />
    <axis
      xyz="0 0 0" />
    <limit
      lower="-1.57"
      upper="1.57"
      effort="25"
      velocity="0.5" />
  </joint>
  <link
    name="wrist_link">
    <inertial>
      <origin
        xyz="0.0024253 0.0175 0.00046914"
        rpy="0 0 0" />
      <mass
        value="0.070875" />
      <inertia
        ixx="1.9195E-05"
        ixy="-3.0988E-17"
        ixz="-6.7763E-21"
        iyy="2.392E-05"
        iyz="1.7007E-18"
        izz="1.9195E-05" />
    </inertial>
    <visual>
      <origin
        xyz="0 0 0"
        rpy="0 0 0" />
      <geometry>
        <mesh
          filename="package://colarm/meshes/wrist_link.STL" />
      </geometry>
      <material
        name="">
        <color
          rgba="0.79216 0.81961 0.93333 1" />
      </material>
    </visual>
    <collision>
      <origin
        xyz="0 0 0"
        rpy="0 0 0" />
      <geometry>
        <mesh
          filename="package://colarm/meshes/wrist_link.STL" />
      </geometry>
    </collision>
  </link>
  <joint
    name="wrist_joint"
    type="revolute">
    <origin
      xyz="-0.00054474 0.095 -0.00075892"
      rpy="0 1.5162 0" />
    <parent
      link="basewrist_link" />
    <child
      link="wrist_link" />
    <axis
      xyz="-0.99898 0 0.045176" />
    <limit
      lower="-1.57"
      upper="1.57"
      effort="25"
      velocity="0.5" />
  </joint>
</robot>