<?xml version="1.0" encoding="utf-8"?>
<!-- This URDF was automatically created by SolidWorks to URDF Exporter! Originally created by Stephen Brawner (brawner@gmail.com) 
     Commit Version: 1.5.1-0-g916b5db  Build Version: 1.5.7152.31018
     For more information, please see http://wiki.ros.org/sw_urdf_exporter -->
<robot
  name="colllarm">
  <link
    name="base_link">
    <inertial>
      <origin
        xyz="4.1741E-36 0.0042472 -2.3296E-19"
        rpy="0 0 0" />
      <mass
        value="0.118" />
      <inertia
        ixx="0.00022082"
        ixy="-2.5519E-21"
        ixz="-3.3632E-38"
        iyy="0.00042194"
        iyz="2.248E-22"
        izz="0.00022082" />
    </inertial>
    <visual>
      <origin
        xyz="0 0 0"
        rpy="0 0 0" />
      <geometry>
        <mesh
          filename="package://colllarm/meshes/base_link.STL" />
      </geometry>
      <material
        name="">
        <color
          rgba="0.79216 0.81961 0.93333 1" />
      </material>
    </visual>
    <collision>
      <origin
        xyz="0 0 0"
        rpy="0 0 0" />
      <geometry>
        <mesh
          filename="package://colllarm/meshes/base_link.STL" />
      </geometry>
    </collision>
  </link>
  <link
    name="upbase_link">
    <inertial>
      <origin
        xyz="1.185E-17 0.039412 -1.0596E-05"
        rpy="0 0 0" />
      <mass
        value="0.59058" />
      <inertia
        ixx="0.00085911"
        ixy="4.8853E-20"
        ixz="-2.253E-20"
        iyy="0.0008286"
        iyz="-7.7406E-20"
        izz="0.00059494" />
    </inertial>
    <visual>
      <origin
        xyz="0 0 0"
        rpy="0 0 0" />
      <geometry>
        <mesh
          filename="package://colllarm/meshes/upbase_link.STL" />
      </geometry>
      <material
        name="">
        <color
          rgba="0.79216 0.81961 0.93333 1" />
      </material>
    </visual>
    <collision>
      <origin
        xyz="0 0 0"
        rpy="0 0 0" />
      <geometry>
        <mesh
          filename="package://colllarm/meshes/upbase_link.STL" />
      </geometry>
    </collision>
  </link>
  <joint
    name="upbase_joint"
    type="revolute">
    <origin
      xyz="0 0 0.025"
      rpy="1.5708 0 0" />
    <parent
      link="base_link" />
    <child
      link="upbase_link" />
    <axis
      xyz="0 1 0" />
    <limit
      lower="-1.57"
      upper="1.57"
      effort="5"
      velocity="0.5" />
  </joint>
  <link
    name="prox_link">
    <inertial>
      <origin
        xyz="-0.0381 -0.15653 0.04502"
        rpy="0 0 0" />
      <mass
        value="1.9456" />
      <inertia
        ixx="0.014446"
        ixy="-4.0564E-19"
        ixz="-1.3614E-19"
        iyy="0.0022969"
        iyz="2.3823E-19"
        izz="0.014015" />
    </inertial>
    <visual>
      <origin
        xyz="0 0 0"
        rpy="0 0 0" />
      <geometry>
        <mesh
          filename="package://colllarm/meshes/prox_link.STL" />
      </geometry>
      <material
        name="">
        <color
          rgba="0.79216 0.81961 0.93333 1" />
      </material>
    </visual>
    <collision>
      <origin
        xyz="0 0 0"
        rpy="0 0 0" />
      <geometry>
        <mesh
          filename="package://colllarm/meshes/prox_link.STL" />
      </geometry>
    </collision>
  </link>
  <joint
    name="prox_joint"
    type="revolute">
    <origin
      xyz="0.0381 0.044438 0.4314"
      rpy="1.5708 0 0" />
    <parent
      link="base_link" />
    <child
      link="prox_link" />
    <axis
      xyz="0 0 1" />
    <limit
      lower="-1.57"
      upper="1.57"
      effort="5"
      velocity="0.5" />
  </joint>
  <link
    name="distal_link">
    <inertial>
      <origin
        xyz="1.3718E-17 0.2007 0.00066865"
        rpy="0 0 0" />
      <mass
        value="2.0206" />
      <inertia
        ixx="0.019596"
        ixy="-3.1694E-19"
        ixz="-1.4063E-20"
        iyy="0.0020846"
        iyz="-3.9705E-20"
        izz="0.019451" />
    </inertial>
    <visual>
      <origin
        xyz="0 0 0"
        rpy="0 0 0" />
      <geometry>
        <mesh
          filename="package://colllarm/meshes/distal_link.STL" />
      </geometry>
      <material
        name="">
        <color
          rgba="0.79216 0.81961 0.93333 1" />
      </material>
    </visual>
    <collision>
      <origin
        xyz="0 0 0"
        rpy="0 0 0" />
      <geometry>
        <mesh
          filename="package://colllarm/meshes/distal_link.STL" />
      </geometry>
    </collision>
  </link>
  <joint
    name="distal_joint"
    type="revolute">
    <origin
      xyz="0 0 0.41235"
      rpy="1.5708 0 0" />
    <parent
      link="base_link" />
    <child
      link="distal_link" />
    <axis
      xyz="0 0 1" />
    <limit
      lower="-1.57"
      upper="1.57"
      effort="5"
      velocity="0.5" />
  </joint>
  <link
    name="wrist_link">
    <inertial>
      <origin
        xyz="3.3396E-18 0.079757 0.0012182"
        rpy="0 0 0" />
      <mass
        value="0.48493" />
      <inertia
        ixx="0.00059851"
        ixy="-9.8281E-20"
        ixz="-1.8489E-20"
        iyy="0.00043866"
        iyz="-1.6924E-20"
        izz="0.0006197" />
    </inertial>
    <visual>
      <origin
        xyz="0 0 0"
        rpy="0 0 0" />
      <geometry>
        <mesh
          filename="package://colllarm/meshes/wrist_link.STL" />
      </geometry>
      <material
        name="">
        <color
          rgba="0.79216 0.81961 0.93333 1" />
      </material>
    </visual>
    <collision>
      <origin
        xyz="0 0 0"
        rpy="0 0 0" />
      <geometry>
        <mesh
          filename="package://colllarm/meshes/wrist_link.STL" />
      </geometry>
    </collision>
  </link>
  <joint
    name="wrist_joint"
    type="revolute">
    <origin
      xyz="0 0 0.77425"
      rpy="1.5708 0 0" />
    <parent
      link="base_link" />
    <child
      link="wrist_link" />
    <axis
      xyz="0 0 1" />
    <limit
      lower="-1.57"
      upper="1.57"
      effort="5"
      velocity="0.5" />
  </joint>
  <link
    name="subfing_link">
    <inertial>
      <origin
        xyz="4.0484E-08 0.038827 -8.6736E-19"
        rpy="0 0 0" />
      <mass
        value="0.25544" />
      <inertia
        ixx="0.000173"
        ixy="-4.8498E-10"
        ixz="-1.1374E-21"
        iyy="0.0001701"
        iyz="-2.7126E-21"
        izz="0.00025541" />
    </inertial>
    <visual>
      <origin
        xyz="0 0 0"
        rpy="0 0 0" />
      <geometry>
        <mesh
          filename="package://colllarm/meshes/subfing_link.STL" />
      </geometry>
      <material
        name="">
        <color
          rgba="0.79216 0.81961 0.93333 1" />
      </material>
    </visual>
    <collision>
      <origin
        xyz="0 0 0"
        rpy="0 0 0" />
      <geometry>
        <mesh
          filename="package://colllarm/meshes/subfing_link.STL" />
      </geometry>
    </collision>
  </link>
  <joint
    name="subfing_link"
    type="revolute">
    <origin
      xyz="0 -0.0012182 0.90861"
      rpy="1.5708 0 0" />
    <parent
      link="base_link" />
    <child
      link="subfing_link" />
    <axis
      xyz="0 1 0" />
    <limit
      lower="-1.57"
      upper="1.57"
      effort="5"
      velocity="0.5" />
  </joint>
  <link
    name="finger1_link">
    <inertial>
      <origin
        xyz="-0.019322 -0.0023864 0.020103"
        rpy="0 0 0" />
      <mass
        value="0.082612" />
      <inertia
        ixx="4.4181E-05"
        ixy="-1.8224E-06"
        ixz="-2.7174E-12"
        iyy="2.0259E-05"
        iyz="8.9567E-12"
        izz="4.1119E-05" />
    </inertial>
    <visual>
      <origin
        xyz="0 0 0"
        rpy="0 0 0" />
      <geometry>
        <mesh
          filename="package://colllarm/meshes/finger1_link.STL" />
      </geometry>
      <material
        name="">
        <color
          rgba="0.79216 0.81961 0.93333 1" />
      </material>
    </visual>
    <collision>
      <origin
        xyz="0 0 0"
        rpy="0 0 0" />
      <geometry>
        <mesh
          filename="package://colllarm/meshes/finger1_link.STL" />
      </geometry>
    </collision>
  </link>
  <joint
    name="finger2_joint"
    type="prismatic">
    <origin
      xyz="0 0.018258 1.034"
      rpy="1.5708 0 0" />
    <parent
      link="base_link" />
    <child
      link="finger1_link" />
    <axis
      xyz="0 0 1" />
    <limit
      lower="-1.57"
      upper="1.57"
      effort="5"
      velocity="0.5" />
  </joint>
  <link
    name="finger2_link">
    <inertial>
      <origin
        xyz="4.1741E-36 0.0042472 -2.3296E-19"
        rpy="0 0 0" />
      <mass
        value="0.118" />
      <inertia
        ixx="0.00022082"
        ixy="-2.5519E-21"
        ixz="-3.3632E-38"
        iyy="0.00042194"
        iyz="2.248E-22"
        izz="0.00022082" />
    </inertial>
    <visual>
      <origin
        xyz="0 0 0"
        rpy="0 0 0" />
      <geometry>
        <mesh
          filename="package://colllarm/meshes/finger2_link.STL" />
      </geometry>
      <material
        name="">
        <color
          rgba="0.79216 0.81961 0.93333 1" />
      </material>
    </visual>
    <collision>
      <origin
        xyz="0 0 0"
        rpy="0 0 0" />
      <geometry>
        <mesh
          filename="package://colllarm/meshes/finger2_link.STL" />
      </geometry>
    </collision>
  </link>
  <joint
    name="finger2_joint"
    type="prismatic">
    <origin
      xyz="0.01905 -0.021742 1.034"
      rpy="1.5708 0 3.1416" />
    <parent
      link="base_link" />
    <child
      link="finger2_link" />
    <axis
      xyz="0 0 -1" />
    <limit
      lower="-1.57"
      upper="1.57"
      effort="5"
      velocity="0.5" />
  </joint>
</robot>